Workbook

Sheet Trang tính1
A1: TT | B1: Họ và tên | C1: MSV | D1: Lớp | E1: Email | F1: Số điện thoại | G1: Năm 1 | K1: Năm 2 | O1: Năm 3 | S1: Năm 4 | T1: GPA
G2: Triết Học Mác-lênin(3) | H2: Tin đại cương(3) | I2: Giải tích(2) | J2: Đại số tuyến tính(3) | K2: Thiết kế web(3) | L2: Lập trình hướng đối tượng(3) | M2: Cấu trúc dữ liệu và giải thuật(3) | N2: Tư tưởng Hồ Chí Minh(2) | O2: Lập trình Web(3) | P2: Lập trình trực quan(3) | Q2: Thuật toán và ứng dụng(3) | R2: Mạng máy tính(3) | S2: Bảo vệ đồ án(10)
A3: =ROW()-2 | B3: CHU ĐỨC ÁNH | C3: 251230808 | D3: Công nghệ thông tin 1 K66 | E3: anh251230808@lms.utc.edu.vn | F3: 0987650003 | G3: 2.7 | H3: 3.2 | I3: 3.3 | J3: 3.2 | K3: 2.5 | L3: 2.8 | M3: 2.4 | N3: 2.3 | O3: 2 | P3: 3.1 | Q3: 2.6 | R3: 2.4 | S3: 3.8 | T3: =(G3*3 + H3*3 + I3*2 + J3*3 + K3*3 + L3*3 + M3*3 + N3*2 + O3*3 + P3*3 + Q3*3 + R3*3 + S3*10) / 44
A4: =ROW()-2 | B4: LÊ QUANG ANH | C4: 251210800 | D4: Công nghệ thông tin 1 K66 | E4: anh251210800@lms.utc.edu.vn | F4: 0987650004 | G4: 3.4 | H4: 2.7 | I4: 2.4 | J4: 3.3 | K4: 1.9 | L4: 2.1 | M4: 3.4 | N4: 4 | O4: 3.9 | P4: 3.8 | Q4: 2.1 | R4: 3.9 | S4: 2.4 | T4: =(G4*3 + H4*3 + I4*2 + J4*3 + K4*3 + L4*3 + M4*3 + N4*2 + O4*3 + P4*3 + Q4*3 + R4*3 + S4*10) / 44
A5: =ROW()-2 | B5: NGÔ AN ĐỨC ANH | C5: 251230801 | D5: Công nghệ thông tin 1 K66 | E5: anh251230801@lms.utc.edu.vn | F5: 0987650005 | G5: 2 | H5: 3.2 | I5: 1.9 | J5: 3.3 | K5: 2.4 | L5: 3.7 | M5: 3.9 | N5: 3.5 | O5: 4 | P5: 2.4 | Q5: 2.7 | R5: 2.6 | S5: 3.7 | T5: =(G5*3 + H5*3 + I5*2 + J5*3 + K5*3 + L5*3 + M5*3 + N5*2 + O5*3 + P5*3 + Q5*3 + R5*3 + S5*10) / 44
A6: =ROW()-2 | B6: TÔ VIỆT ANH | C6: 251230807 | D6: Công nghệ thông tin 1 K66 | E6: anh251230807@lms.utc.edu.vn | F6: 0987650006 | G6: 1.8 | H6: 1.8 | I6: 3.1 | J6: 0.4 | K6: 2 | L6: 2.9 | M6: 3.8 | N6: 2.4 | O6: 2.6 | P6: 2.2 | Q6: 3.8 | R6: 3.4 | S6: 3.8 | T6: =(G6*3 + H6*3 + I6*2 + J6*3 + K6*3 + L6*3 + M6*3 + N6*2 + O6*3 + P6*3 + Q6*3 + R6*3 + S6*10) / 44
A7: =ROW()-2 | B7: TRẦN MẬU BẮC | C7: 251230813 | D7: Công nghệ thông tin 1 K66 | E7: bac251230813@lms.utc.edu.vn | F7: 0987650007 | G7: 2.1 | H7: 2.5 | I7: 2 | J7: 1 | K7: 2.1 | L7: 2.9 | M7: 3.1 | N7: 4 | O7: 2.6 | P7: 1.8 | Q7: 3.4 | R7: 3.8 | S7: 3.8 | T7: =(G7*3 + H7*3 + I7*2 + J7*3 + K7*3 + L7*3 + M7*3 + N7*2 + O7*3 + P7*3 + Q7*3 + R7*3 + S7*10) / 44
A8: =ROW()-2 | B8: NGUYỄN VĂN CHÍ BẢO | C8: 251230811 | D8: Công nghệ thông tin 1 K66 | E8: bao251230811@lms.utc.edu.vn | F8: 0987650008 | G8: 1.9 | H8: 2.1 | I8: 3.5 | J8: 0.9 | K8: 3.8 | L8: 3.4 | M8: 2.9 | N8: 2.1 | O8: 3.8 | P8: 3.2 | Q8: 3.9 | R8: 3.6 | S8: 3.9 | T8: =(G8*3 + H8*3 + I8*2 + J8*3 + K8*3 + L8*3 + M8*3 + N8*2 + O8*3 + P8*3 + Q8*3 + R8*3 + S8*10) / 44
A9: =ROW()-2 | B9: NGUYỄN VĂN GIA BẢO | C9: 251230812 | D9: Công nghệ thông tin 1 K66 | E9: bao251230812@lms.utc.edu.vn | F9: 0987650009 | G9: 2 | H9: 2.1 | I9: 3.5 | J9: 1.3 | K9: 2.7 | L9: 2.5 | M9: 2.1 | N9: 3.8 | O9: 3.3 | P9: 2.8 | Q9: 3.9 | R9: 2.2 | S9: 3.4 | T9: =(G9*3 + H9*3 + I9*2 + J9*3 + K9*3 + L9*3 + M9*3 + N9*2 + O9*3 + P9*3 + Q9*3 + R9*3 + S9*10) / 44
A10: =ROW()-2 | B10: NGUYỄN ĐỨC CƯƠNG | C10: 251210818 | D10: Công nghệ thông tin 1 K66 | E10: cuong251210818@lms.utc.edu.vn | F10: 0987650010 | G10: 3.4 | H10: 3.5 | I10: 3.9 | J10: 0.5 | K10: 3.4 | L10: 3.5 | M10: 3.4 | N10: 3.7 | O10: 3.4 | P10: 1.9 | Q10: 2.8 | R10: 2.8 | S10: 3 | T10: =(G10*3 + H10*3 + I10*2 + J10*3 + K10*3 + L10*3 + M10*3 + N10*2 + O10*3 + P10*3 + Q10*3 + R10*3 + S10*10) / 44
A11: =ROW()-2 | B11: VŨ MẠNH CƯỜNG | C11: 251230821 | D11: Công nghệ thông tin 1 K66 | E11: cuong251230821@lms.utc.edu.vn | F11: 0987650011 | G11: 2.1 | H11: 2.5 | I11: 3.9 | J11: 2.8 | K11: 3.3 | L11: 3 | M11: 3.1 | N11: 4 | O11: 3.8 | P11: 2.4 | Q11: 1.9 | R11: 3.5 | S11: 3.8 | T11: =(G11*3 + H11*3 + I11*2 + J11*3 + K11*3 + L11*3 + M11*3 + N11*2 + O11*3 + P11*3 + Q11*3 + R11*3 + S11*10) / 44
A12: =ROW()-2 | B12: NGUYỄN KHÁNH DOANH | C12: 251230822 | D12: Công nghệ thông tin 1 K66 | E12: doanh251230822@lms.utc.edu.vn | F12: 0987650012 | G12: 2.1 | H12: 3.4 | I12: 3.3 | J12: 0.3 | K12: 3.6 | L12: 2.5 | M12: 1.8 | N12: 2.5 | O12: 2.6 | P12: 2.6 | Q12: 2.3 | R12: 3.7 | S12: 2.3 | T12: =(G12*3 + H12*3 + I12*2 + J12*3 + K12*3 + L12*3 + M12*3 + N12*2 + O12*3 + P12*3 + Q12*3 + R12*3 + S12*10) / 44
A13: =ROW()-2 | B13: ĐỖ QUANG DŨNG | C13: 251210825 | D13: Công nghệ thông tin 1 K66 | E13: dung251210825@lms.utc.edu.vn | F13: 0987650013 | G13: 3.1 | H13: 3.1 | I13: 2 | J13: 2.7 | K13: 2.2 | L13: 3.2 | M13: 2.4 | N13: 2.5 | O13: 2.9 | P13: 3.3 | Q13: 2.3 | R13: 2.6 | S13: 2.6 | T13: =(G13*3 + H13*3 + I13*2 + J13*3 + K13*3 + L13*3 + M13*3 + N13*2 + O13*3 + P13*3 + Q13*3 + R13*3 + S13*10) / 44
A14: =ROW()-2 | B14: NGUYỄN TÙNG DƯƠNG | C14: 251210833 | D14: Công nghệ thông tin 1 K66 | E14: duong251210833@lms.utc.edu.vn | F14: 0987650014 | G14: 3 | H14: 2.6 | I14: 2.3 | J14: 3.1 | K14: 3 | L14: 2 | M14: 2.9 | N14: 2.4 | O14: 2.2 | P14: 3.6 | Q14: 2.5 | R14: 2.6 | S14: 3.7 | T14: =(G14*3 + H14*3 + I14*2 + J14*3 + K14*3 + L14*3 + M14*3 + N14*2 + O14*3 + P14*3 + Q14*3 + R14*3 + S14*10) / 44
... A257: =ROW()-2 | B257: NGUYỄN ĐĂNG VIỆT | C257: 253610701 | D257: Khoa học máy tính K66 | E257: viet253610701@lms.utc.edu.vn | F257: 0987650257 | G257: 1.8 | H257: 2.4 | I257: 2.2 | J257: 0.4 | K257: 1.9 | L257: 1.9 | M257: 3.3 | N257: 2.3 | O257: 4 | P257: 3.9 | Q257: 3.1 | R257: 3.5 | S257: 2.5 | T257: =(G257*3 + H257*3 + I257*2 + J257*3 + K257*3 + L257*3 + M257*3 + N257*2 + O257*3 + P257*3 + Q257*3 + R257*3 + S257*10) / 44

Sheet TKB Chính Thức (Ban Ngày)
A1: THỜI KHÓA BIỂU CHÍNH THỨC (4 CA BAN NGÀY)
A3: Năm học | B3: Lớp | C3: Môn học | D3: Thứ học | E3: Ca học ban ngày
A4: Năm 1 | B4: Công nghệ thông tin 1 K66 | C4: Triết Học Mác-lênin(3) | D4: Thứ 2 | E4: Ca 4 (Tiết 10-12)
A5: Năm 1 | B5: Công nghệ thông tin 1 K66 | C5: Tin đại cương(3) | D5: Thứ 4 | E5: Ca 3 (Tiết 7-9)
A6: Năm 1 | B6: Công nghệ thông tin 1 K66 | C6: Giải tích(2) | D6: Thứ 6 | E6: Ca 1 (Tiết 1-3)
A7: Năm 1 | B7: Công nghệ thông tin 1 K66 | C7: Đại số tuyến tính(3) | D7: Thứ 7 | E7: Ca 1 (Tiết 1-3)
A8: Năm 1 | B8: Công nghệ thông tin 2 K66 | C8: Triết Học Mác-lênin(3) | D8: Thứ 2 | E8: Ca 4 (Tiết 10-12)
A9: Năm 1 | B9: Công nghệ thông tin 2 K66 | C9: Tin đại cương(3) | D9: Thứ 3 | E9: Ca 4 (Tiết 10-12)
A10: Năm 1 | B10: Công nghệ thông tin 2 K66 | C10: Giải tích(2) | D10: Thứ 6 | E10: Ca 4 (Tiết 10-12)
A11: Năm 1 | B11: Công nghệ thông tin 2 K66 | C11: Đại số tuyến tính(3) | D11: Thứ 6 | E11: Ca 2 (Tiết 4-6)
A12: Năm 1 | B12: Công nghệ thông tin 3 K66 | C12: Triết Học Mác-lênin(3) | D12: Thứ 5 | E12: Ca 2 (Tiết 4-6)
A13: Năm 1 | B13: Công nghệ thông tin 3 K66 | C13: Tin đại cương(3) | D13: Thứ 6 | E13: Ca 3 (Tiết 7-9)
A14: Năm 1 | B14: Công nghệ thông tin 3 K66 | C14: Giải tích(2) | D14: Thứ 6 | E14: Ca 2 (Tiết 4-6)
... A55: Năm 4 | B55: Khoa học máy tính K66 | C55: Bảo vệ đồ án(10) | D55: Thứ 5 | E55: Ca 3 (Tiết 7-9)

Sheet Lịch Phụ Đạo Tối (GPA < 2.0)
A1: LỊCH HỌC PHỤ ĐẠO BUỔI TỐI (DÀNH CHO SV CÓ ĐIỂM MÔN < 2.0)
A3: Năm học | B3: Môn học phụ đạo | C3: Thứ học | D3: Ca học buổi tối | E3: Đối tượng tham gia
A4: Năm 1 | B4: Triết Học Mác-lênin(3) | C4: Thứ 5 | D4: Ca Tối (18:00 - 20:00) | E4: Tất cả SV các lớp có điểm môn < 2.0 (Học chung ca)
A5: Năm 1 | B5: Tin đại cương(3) | C5: Thứ 2 | D5: Ca Tối (18:00 - 20:00) | E5: Tất cả SV các lớp có điểm môn < 2.0 (Học chung ca)
A6: Năm 1 | B6: Giải tích(2) | C6: Thứ 7 | D6: Ca Tối (18:00 - 20:00) | E6: Tất cả SV các lớp có điểm môn < 2.0 (Học chung ca)
A7: Năm 1 | B7: Đại số tuyến tính(3) | C7: Thứ 4 | D7: Ca Tối (18:00 - 20:00) | E7: Tất cả SV các lớp có điểm môn < 2.0 (Học chung ca)
A8: Năm 2 | B8: Thiết kế web(3) | C8: Thứ 6 | D8: Ca Tối (18:00 - 20:00) | E8: Tất cả SV các lớp có điểm môn < 2.0 (Học chung ca)
A9: Năm 2 | B9: Lập trình hướng đối tượng(3) | C9: Thứ 5 | D9: Ca Tối (18:00 - 20:00) | E9: Tất cả SV các lớp có điểm môn < 2.0 (Học chung ca)
A10: Năm 2 | B10: Cấu trúc dữ liệu và giải thuật(3) | C10: Thứ 2 | D10: Ca Tối (18:00 - 20:00) | E10: Tất cả SV các lớp có điểm môn < 2.0 (Học chung ca)
A11: Năm 2 | B11: Tư tưởng Hồ Chí Minh(2) | C11: Thứ 3 | D11: Ca Tối (18:00 - 20:00) | E11: Tất cả SV các lớp có điểm môn < 2.0 (Học chung ca)
A12: Năm 3 | B12: Lập trình Web(3) | C12: Thứ 6 | D12: Ca Tối (18:00 - 20:00) | E12: Tất cả SV các lớp có điểm môn < 2.0 (Học chung ca)
A13: Năm 3 | B13: Lập trình trực quan(3) | C13: Thứ 7 | D13: Ca Tối (18:00 - 20:00) | E13: Tất cả SV các lớp có điểm môn < 2.0 (Học chung ca)
A14: Năm 3 | B14: Thuật toán và ứng dụng(3) | C14: Thứ 5 | D14: Ca Tối (18:00 - 20:00) | E14: Tất cả SV các lớp có điểm môn < 2.0 (Học chung ca)
... A16: Năm 4 | B16: Bảo vệ đồ án(10) | C16: Thứ 6 | D16: Ca Tối (18:00 - 20:00) | E16: Tất cả SV các lớp có điểm môn < 2.0 (Học chung ca)

Sheet Danh Sách SV Phụ Đạo Tối
A1: DANH SÁCH SINH VIÊN BẮC BUỘC HỌC PHỤ ĐẠO BUỔI TỐI (ĐIỂM MÔN < 2.0)
A3: MSV | B3: Họ và tên | C3: Lớp | D3: Năm học | E3: Môn học cần phụ đạo | F3: Điểm HP | G3: Lịch học phụ đạo tối
A4: 251210800 | B4: LÊ QUANG ANH | C4: Công nghệ thông tin 1 K66 | D4: Năm 2 | E4: Thiết kế web(3) | F4: 1.9 | G4: Thứ 6 (Ca Tối (18:00 - 20:00))
A5: 251230801 | B5: NGÔ AN ĐỨC ANH | C5: Công nghệ thông tin 1 K66 | D5: Năm 1 | E5: Giải tích(2) | F5: 1.9 | G5: Thứ 7 (Ca Tối (18:00 - 20:00))
A6: 251230807 | B6: TÔ VIỆT ANH | C6: Công nghệ thông tin 1 K66 | D6: Năm 1 | E6: Triết Học Mác-lênin(3) | F6: 1.8 | G6: Thứ 5 (Ca Tối (18:00 - 20:00))
A7: 251230807 | B7: TÔ VIỆT ANH | C7: Công nghệ thông tin 1 K66 | D7: Năm 1 | E7: Tin đại cương(3) | F7: 1.8 | G7: Thứ 2 (Ca Tối (18:00 - 20:00))
A8: 251230807 | B8: TÔ VIỆT ANH | C8: Công nghệ thông tin 1 K66 | D8: Năm 1 | E8: Đại số tuyến tính(3) | F8: 0.4 | G8: Thứ 4 (Ca Tối (18:00 - 20:00))
A9: 251230813 | B9: TRẦN MẬU BẮC | C9: Công nghệ thông tin 1 K66 | D9: Năm 1 | E9: Đại số tuyến tính(3) | F9: 1 | G9: Thứ 4 (Ca Tối (18:00 - 20:00))
A10: 251230813 | B10: TRẦN MẬU BẮC | C10: Công nghệ thông tin 1 K66 | D10: Năm 3 | E10: Lập trình trực quan(3) | F10: 1.8 | G10: Thứ 7 (Ca Tối (18:00 - 20:00))
A11: 251230811 | B11: NGUYỄN VĂN CHÍ BẢO | C11: Công nghệ thông tin 1 K66 | D11: Năm 1 | E11: Triết Học Mác-lênin(3) | F11: 1.9 | G11: Thứ 5 (Ca Tối (18:00 - 20:00))
A12: 251230811 | B12: NGUYỄN VĂN CHÍ BẢO | C12: Công nghệ thông tin 1 K66 | D12: Năm 1 | E12: Đại số tuyến tính(3) | F12: 0.9 | G12: Thứ 4 (Ca Tối (18:00 - 20:00))
A13: 251230812 | B13: NGUYỄN VĂN GIA BẢO | C13: Công nghệ thông tin 1 K66 | D13: Năm 1 | E13: Đại số tuyến tính(3) | F13: 1.3 | G13: Thứ 4 (Ca Tối (18:00 - 20:00))
A14: 251210818 | B14: NGUYỄN ĐỨC CƯƠNG | C14: Công nghệ thông tin 1 K66 | D14: Năm 1 | E14: Đại số tuyến tính(3) | F14: 0.5 | G14: Thứ 4 (Ca Tối (18:00 - 20:00))
A15: 251210818 | B15: NGUYỄN ĐỨC CƯƠNG | C15: Công nghệ thông tin 1 K66 | D15: Năm 3 | E15: Lập trình trực quan(3) | F15: 1.9 | G15: Thứ 7 (Ca Tối (18:00 - 20:00))
... A381: 253610701 | B381: NGUYỄN ĐĂNG VIỆT | C381: Khoa học máy tính K66 | D381: Năm 2 | E381: Lập trình hướng đối tượng(3) | F381: 1.9 | G381: Thứ 5 (Ca Tối (18:00 - 20:00))

Sheet Cấu Hình Học Phí
A1: CẤU HÌNH HỌC PHÍ
A3: Học phí cơ bản / môn (Năm 1) | B3: 550000
A4: Mức tăng mỗi năm | B4: 0.1
A5: Phí phụ đạo / môn (điểm < 2.0) | B5: 1000000
A7: Năm học | B7: Đơn giá / môn | C7: Năm học (niên khóa)
A8: Năm 1 | B8: =ROUND($B$3*(1+$B$4)^0,0) | C8: 2025_2026
A9: Năm 2 | B9: =ROUND($B$3*(1+$B$4)^1,0) | C9: 2026_2027
A10: Năm 3 | B10: =ROUND($B$3*(1+$B$4)^2,0) | C10: 2027_2028
A11: Năm 4 | B11: =ROUND($B$3*(1+$B$4)^3,0) | C11: 2028_2029

Sheet Chi Tiết Học Phí
A1: CHI TIẾT HỌC PHÍ THEO NĂM HỌC
A3: MSV | B3: Họ và tên | C3: Lớp | D3: Năm học | E3: Niên khóa | F3: Số môn | G3: Đơn giá / môn | H3: Học phí môn học | I3: Số môn phụ đạo | J3: Phí phụ đạo | K3: Miễn giảm | L3: Phải nộp | M3: Đã nộp | N3: Đã rút | O3: Thừa | P3: Còn nợ | Q3: Hạn nộp | R3: Số phiếu thu | S3: Ghi chú
A4: 251230808 | B4: CHU ĐỨC ÁNH | C4: Công nghệ thông tin 1 K66 | D4: Năm 1 | E4: 2025_2026 | F4: 4 | G4: =VLOOKUP(D4,'Cấu Hình Học Phí'!$A$8:$B$11,2,FALSE) | H4: =F4*G4 | I4: 0 | J4: =I4*'Cấu Hình Học Phí'!$B$5 | K4: 0 | L4: =H4+J4-K4 | M4: 2200000 | N4: 0 | O4: =MAX(0,M4-N4-L4) | P4: =MAX(0,L4-(M4-N4)) | Q4: 30/09/2025 | R4: PT2025-00001
A5: 251230808 | B5: CHU ĐỨC ÁNH | C5: Công nghệ thông tin 1 K66 | D5: Năm 2 | E5: 2026_2027 | F5: 4 | G5: =VLOOKUP(D5,'Cấu Hình Học Phí'!$A$8:$B$11,2,FALSE) | H5: =F5*G5 | I5: 0 | J5: =I5*'Cấu Hình Học Phí'!$B$5 | K5: 0 | L5: =H5+J5-K5 | M5: 2420000 | N5: 0 | O5: =MAX(0,M5-N5-L5) | P5: =MAX(0,L5-(M5-N5)) | Q5: 30/09/2026 | R5: PT2026-00002
A6: 251230808 | B6: CHU ĐỨC ÁNH | C6: Công nghệ thông tin 1 K66 | D6: Năm 3 | E6: 2027_2028 | F6: 4 | G6: =VLOOKUP(D6,'Cấu Hình Học Phí'!$A$8:$B$11,2,FALSE) | H6: =F6*G6 | I6: 0 | J6: =I6*'Cấu Hình Học Phí'!$B$5 | K6: 0 | L6: =H6+J6-K6 | M6: 2662000 | N6: 0 | O6: =MAX(0,M6-N6-L6) | P6: =MAX(0,L6-(M6-N6)) | Q6: 30/09/2027 | R6: PT2027-00003
A7: 251230808 | B7: CHU ĐỨC ÁNH | C7: Công nghệ thông tin 1 K66 | D7: Năm 4 | E7: 2028_2029 | F7: 1 | G7: =VLOOKUP(D7,'Cấu Hình Học Phí'!$A$8:$B$11,2,FALSE) | H7: =F7*G7 | I7: 0 | J7: =I7*'Cấu Hình Học Phí'!$B$5 | K7: 0 | L7: =H7+J7-K7 | M7: 732050 | N7: 0 | O7: =MAX(0,M7-N7-L7) | P7: =MAX(0,L7-(M7-N7)) | Q7: 30/09/2028 | R7: PT2028-00004
A8: 251210800 | B8: LÊ QUANG ANH | C8: Công nghệ thông tin 1 K66 | D8: Năm 1 | E8: 2025_2026 | F8: 4 | G8: =VLOOKUP(D8,'Cấu Hình Học Phí'!$A$8:$B$11,2,FALSE) | H8: =F8*G8 | I8: 0 | J8: =I8*'Cấu Hình Học Phí'!$B$5 | K8: 0 | L8: =H8+J8-K8 | M8: 2200000 | N8: 0 | O8: =MAX(0,M8-N8-L8) | P8: =MAX(0,L8-(M8-N8)) | Q8: 30/09/2025 | R8: PT2025-00005
A9: 251210800 | B9: LÊ QUANG ANH | C9: Công nghệ thông tin 1 K66 | D9: Năm 2 | E9: 2026_2027 | F9: 4 | G9: =VLOOKUP(D9,'Cấu Hình Học Phí'!$A$8:$B$11,2,FALSE) | H9: =F9*G9 | I9: 1 | J9: =I9*'Cấu Hình Học Phí'!$B$5 | K9: 0 | L9: =H9+J9-K9 | M9: 3420000 | N9: 0 | O9: =MAX(0,M9-N9-L9) | P9: =MAX(0,L9-(M9-N9)) | Q9: 30/09/2026 | R9: PT2026-00006
A10: 251210800 | B10: LÊ QUANG ANH | C10: Công nghệ thông tin 1 K66 | D10: Năm 3 | E10: 2027_2028 | F10: 4 | G10: =VLOOKUP(D10,'Cấu Hình Học Phí'!$A$8:$B$11,2,FALSE) | H10: =F10*G10 | I10: 0 | J10: =I10*'Cấu Hình Học Phí'!$B$5 | K10: 0 | L10: =H10+J10-K10 | M10: 2662000 | N10: 0 | O10: =MAX(0,M10-N10-L10) | P10: =MAX(0,L10-(M10-N10)) | Q10: 30/09/2027 | R10: PT2027-00007
A11: 251210800 | B11: LÊ QUANG ANH | C11: Công nghệ thông tin 1 K66 | D11: Năm 4 | E11: 2028_2029 | F11: 1 | G11: =VLOOKUP(D11,'Cấu Hình Học Phí'!$A$8:$B$11,2,FALSE) | H11: =F11*G11 | I11: 0 | J11: =I11*'Cấu Hình Học Phí'!$B$5 | K11: 0 | L11: =H11+J11-K11 | M11: 732050 | N11: 0 | O11: =MAX(0,M11-N11-L11) | P11: =MAX(0,L11-(M11-N11)) | Q11: 30/09/2028 | R11: PT2028-00008
A12: 251230801 | B12: NGÔ AN ĐỨC ANH | C12: Công nghệ thông tin 1 K66 | D12: Năm 1 | E12: 2025_2026 | F12: 4 | G12: =VLOOKUP(D12,'Cấu Hình Học Phí'!$A$8:$B$11,2,FALSE) | H12: =F12*G12 | I12: 1 | J12: =I12*'Cấu Hình Học Phí'!$B$5 | K12: 0 | L12: =H12+J12-K12 | M12: 3200000 | N12: 0 | O12: =MAX(0,M12-N12-L12) | P12: =MAX(0,L12-(M12-N12)) | Q12: 30/09/2025 | R12: PT2025-00009
A13: 251230801 | B13: NGÔ AN ĐỨC ANH | C13: Công nghệ thông tin 1 K66 | D13: Năm 2 | E13: 2026_2027 | F13: 4 | G13: =VLOOKUP(D13,'Cấu Hình Học Phí'!$A$8:$B$11,2,FALSE) | H13: =F13*G13 | I13: 0 | J13: =I13*'Cấu Hình Học Phí'!$B$5 | K13: 0 | L13: =H13+J13-K13 | M13: 2420000 | N13: 0 | O13: =MAX(0,M13-N13-L13) | P13: =MAX(0,L13-(M13-N13)) | Q13: 30/09/2026 | R13: PT2026-00010
A14: 251230801 | B14: NGÔ AN ĐỨC ANH | C14: Công nghệ thông tin 1 K66 | D14: Năm 3 | E14: 2027_2028 | F14: 4 | G14: =VLOOKUP(D14,'Cấu Hình Học Phí'!$A$8:$B$11,2,FALSE) | H14: =F14*G14 | I14: 0 | J14: =I14*'Cấu Hình Học Phí'!$B$5 | K14: 0 | L14: =H14+J14-K14 | M14: 2662000 | N14: 0 | O14: =MAX(0,M14-N14-L14) | P14: =MAX(0,L14-(M14-N14)) | Q14: 30/09/2027 | R14: PT2027-00011
A15: 251230801 | B15: NGÔ AN ĐỨC ANH | C15: Công nghệ thông tin 1 K66 | D15: Năm 4 | E15: 2028_2029 | F15: 1 | G15: =VLOOKUP(D15,'Cấu Hình Học Phí'!$A$8:$B$11,2,FALSE) | H15: =F15*G15 | I15: 0 | J15: =I15*'Cấu Hình Học Phí'!$B$5 | K15: 0 | L15: =H15+J15-K15 | M15: 732050 | N15: 0 | O15: =MAX(0,M15-N15-L15) | P15: =MAX(0,L15-(M15-N15)) | Q15: 30/09/2028 | R15: PT2028-00012
A16: 251230807 | B16: TÔ VIỆT ANH | C16: Công nghệ thông tin 1 K66 | D16: Năm 1 | E16: 2025_2026 | F16: 4 | G16: =VLOOKUP(D16,'Cấu Hình Học Phí'!$A$8:$B$11,2,FALSE) | H16: =F16*G16 | I16: 3 | J16: =I16*'Cấu Hình Học Phí'!$B$5 | K16: 0 | L16: =H16+J16-K16 | M16: 4200000 | N16: 0 | O16: =MAX(0,M16-N16-L16) | P16: =MAX(0,L16-(M16-N16)) | Q16: 30/09/2025 | R16: PT2025-00013 | S16: Chưa nộp phí phụ đạo 1 môn
A17: 251230807 | B17: TÔ VIỆT ANH | C17: Công nghệ thông tin 1 K66 | D17: Năm 2 | E17: 2026_2027 | F17: 4 | G17: =VLOOKUP(D17,'Cấu Hình Học Phí'!$A$8:$B$11,2,FALSE) | H17: =F17*G17 | I17: 0 | J17: =I17*'Cấu Hình Học Phí'!$B$5 | K17: 0 | L17: =H17+J17-K17 | M17: 2420000 | N17: 0 | O17: =MAX(0,M17-N17-L17) | P17: =MAX(0,L17-(M17-N17)) | Q17: 30/09/2026 | R17: PT2026-00014
A18: 251230807 | B18: TÔ VIỆT ANH | C18: Công nghệ thông tin 1 K66 | D18: Năm 3 | E18: 2027_2028 | F18: 4 | G18: =VLOOKUP(D18,'Cấu Hình Học Phí'!$A$8:$B$11,2,FALSE) | H18: =F18*G18 | I18: 0 | J18: =I18*'Cấu Hình Học Phí'!$B$5 | K18: 0 | L18: =H18+J18-K18 | M18: 2662000 | N18: 0 | O18: =MAX(0,M18-N18-L18) | P18: =MAX(0,L18-(M18-N18)) | Q18: 30/09/2027 | R18: PT2027-00015
A19: 251230807 | B19: TÔ VIỆT ANH | C19: Công nghệ thông tin 1 K66 | D19: Năm 4 | E19: 2028_2029 | F19: 1 | G19: =VLOOKUP(D19,'Cấu Hình Học Phí'!$A$8:$B$11,2,FALSE) | H19: =F19*G19 | I19: 0 | J19: =I19*'Cấu Hình Học Phí'!$B$5 | K19: 0 | L19: =H19+J19-K19 | M19: 732050 | N19: 0 | O19: =MAX(0,M19-N19-L19) | P19: =MAX(0,L19-(M19-N19)) | Q19: 30/09/2028 | R19: PT2028-00016
A20: 251230813 | B20: TRẦN MẬU BẮC | C20: Công nghệ thông tin 1 K66 | D20: Năm 1 | E20: 2025_2026 | F20: 4 | G20: =VLOOKUP(D20,'Cấu Hình Học Phí'!$A$8:$B$11,2,FALSE) | H20: =F20*G20 | I20: 1 | J20: =I20*'Cấu Hình Học Phí'!$B$5 | K20: 0 | L20: =H20+J20-K20 | M20: 2200000 | N20: 0 | O20: =MAX(0,M20-N20-L20) | P20: =MAX(0,L20-(M20-N20)) | Q20: 30/09/2025 | R20: PT2025-00017 | S20: Chưa nộp phí phụ đạo 1 môn
A21: 251230813 | B21: TRẦN MẬU BẮC | C21: Công nghệ thông tin 1 K66 | D21: Năm 2 | E21: 2026_2027 | F21: 4 | G21: =VLOOKUP(D21,'Cấu Hình Học Phí'!$A$8:$B$11,2,FALSE) | H21: =F21*G21 | I21: 0 | J21: =I21*'Cấu Hình Học Phí'!$B$5 | K21: 0 | L21: =H21+J21-K21 | M21: 2420000 | N21: 0 | O21: =MAX(0,M21-N21-L21) | P21: =MAX(0,L21-(M21-N21)) | Q21: 30/09/2026 | R21: PT2026-00018
A22: 251230813 | B22: TRẦN MẬU BẮC | C22: Công nghệ thông tin 1 K66 | D22: Năm 3 | E22: 2027_2028 | F22: 4 | G22: =VLOOKUP(D22,'Cấu Hình Học Phí'!$A$8:$B$11,2,FALSE) | H22: =F22*G22 | I22: 1 | J22: =I22*'Cấu Hình Học Phí'!$B$5 | K22: 0 | L22: =H22+J22-K22 | M22: 2662000 | N22: 0 | O22: =MAX(0,M22-N22-L22) | P22: =MAX(0,L22-(M22-N22)) | Q22: 30/09/2027 | R22: PT2027-00019 | S22: Chưa nộp phí phụ đạo 1 môn
A23: 251230813 | B23: TRẦN MẬU BẮC | C23: Công nghệ thông tin 1 K66 | D23: Năm 4 | E23: 2028_2029 | F23: 1 | G23: =VLOOKUP(D23,'Cấu Hình Học Phí'!$A$8:$B$11,2,FALSE) | H23: =F23*G23 | I23: 0 | J23: =I23*'Cấu Hình Học Phí'!$B$5 | K23: 0 | L23: =H23+J23-K23 | M23: 732050 | N23: 0 | O23: =MAX(0,M23-N23-L23) | P23: =MAX(0,L23-(M23-N23)) | Q23: 30/09/2028 | R23: PT2028-00020
A24: 251230811 | B24: NGUYỄN VĂN CHÍ BẢO | C24: Công nghệ thông tin 1 K66 | D24: Năm 1 | E24: 2025_2026 | F24: 4 | G24: =VLOOKUP(D24,'Cấu Hình Học Phí'!$A$8:$B$11,2,FALSE) | H24: =F24*G24 | I24: 2 | J24: =I24*'Cấu Hình Học Phí'!$B$5 | K24: 0 | L24: =H24+J24-K24 | M24: 3200000 | N24: 0 | O24: =MAX(0,M24-N24-L24) | P24: =MAX(0,L24-(M24-N24)) | Q24: 30/09/2025 | R24: PT2025-00021 | S24: Chưa nộp phí phụ đạo 1 môn
A25: 251230811 | B25: NGUYỄN VĂN CHÍ BẢO | C25: Công nghệ thông tin 1 K66 | D25: Năm 2 | E25: 2026_2027 | F25: 4 | G25: =VLOOKUP(D25,'Cấu Hình Học Phí'!$A$8:$B$11,2,FALSE) | H25: =F25*G25 | I25: 0 | J25: =I25*'Cấu Hình Học Phí'!$B$5 | K25: 0 | L25: =H25+J25-K25 | M25: 2420000 | N25: 0 | O25: =MAX(0,M25-N25-L25) | P25: =MAX(0,L25-(M25-N25)) | Q25: 30/09/2026 | R25: PT2026-00022
A26: 251230811 | B26: NGUYỄN VĂN CHÍ BẢO | C26: Công nghệ thông tin 1 K66 | D26: Năm 3 | E26: 2027_2028 | F26: 4 | G26: =VLOOKUP(D26,'Cấu Hình Học Phí'!$A$8:$B$11,2,FALSE) | H26: =F26*G26 | I26: 0 | J26: =I26*'Cấu Hình Học Phí'!$B$5 | K26: 0 | L26: =H26+J26-K26 | M26: 2662000 | N26: 0 | O26: =MAX(0,M26-N26-L26) | P26: =MAX(0,L26-(M26-N26)) | Q26: 30/09/2027 | R26: PT2027-00023
A27: 251230811 | B27: NGUYỄN VĂN CHÍ BẢO | C27: Công nghệ thông tin 1 K66 | D27: Năm 4 | E27: 2028_2029 | F27: 1 | G27: =VLOOKUP(D27,'Cấu Hình Học Phí'!$A$8:$B$11,2,FALSE) | H27: =F27*G27 | I27: 0 | J27: =I27*'Cấu Hình Học Phí'!$B$5 | K27: 0 | L27: =H27+J27-K27 | M27: 732050 | N27: 0 | O27: =MAX(0,M27-N27-L27) | P27: =MAX(0,L27-(M27-N27)) | Q27: 30/09/2028 | R27: PT2028-00024
A28: 251230812 | B28: NGUYỄN VĂN GIA BẢO | C28: Công nghệ thông tin 1 K66 | D28: Năm 1 | E28: 2025_2026 | F28: 4 | G28: =VLOOKUP(D28,'Cấu Hình Học Phí'!$A$8:$B$11,2,FALSE) | H28: =F28*G28 | I28: 1 | J28: =I28*'Cấu Hình Học Phí'!$B$5 | K28: 0 | L28: =H28+J28-K28 | M28: 2200000 | N28: 0 | O28: =MAX(0,M28-N28-L28) | P28: =MAX(0,L28-(M28-N28)) | Q28: 30/09/2025 | R28: PT2025-00025 | S28: Chưa nộp phí phụ đạo 1 môn
A29: 251230812 | B29: NGUYỄN VĂN GIA BẢO | C29: Công nghệ thông tin 1 K66 | D29: Năm 2 | E29: 2026_2027 | F29: 4 | G29: =VLOOKUP(D29,'Cấu Hình Học Phí'!$A$8:$B$11,2,FALSE) | H29: =F29*G29 | I29: 0 | J29: =I29*'Cấu Hình Học Phí'!$B$5 | K29: 0 | L29: =H29+J29-K29 | M29: 2420000 | N29: 0 | O29: =MAX(0,M29-N29-L29) | P29: =MAX(0,L29-(M29-N29)) | Q29: 30/09/2026 | R29: PT2026-00026
A30: 251230812 | B30: NGUYỄN VĂN GIA BẢO | C30: Công nghệ thông tin 1 K66 | D30: Năm 3 | E30: 2027_2028 | F30: 4 | G30: =VLOOKUP(D30,'Cấu Hình Học Phí'!$A$8:$B$11,2,FALSE) | H30: =F30*G30 | I30: 0 | J30: =I30*'Cấu Hình Học Phí'!$B$5 | K30: 0 | L30: =H30+J30-K30 | M30: 2662000 | N30: 0 | O30: =MAX(0,M30-N30-L30) | P30: =MAX(0,L30-(M30-N30)) | Q30: 30/09/2027 | R30: PT2027-00027
A31: 251230812 | B31: NGUYỄN VĂN GIA BẢO | C31: Công nghệ thông tin 1 K66 | D31: Năm 4 | E31: 2028_2029 | F31: 1 | G31: =VLOOKUP(D31,'Cấu Hình Học Phí'!$A$8:$B$11,2,FALSE) | H31: =F31*G31 | I31: 0 | J31: =I31*'Cấu Hình Học Phí'!$B$5 | K31: 0 | L31: =H31+J31-K31 | M31: 732050 | N31: 0 | O31: =MAX(0,M31-N31-L31) | P31: =MAX(0,L31-(M31-N31)) | Q31: 30/09/2028 | R31: PT2028-00028
A32: 251210818 | B32: NGUYỄN ĐỨC CƯƠNG | C32: Công nghệ thông tin 1 K66 | D32: Năm 1 | E32: 2025_2026 | F32: 4 | G32: =VLOOKUP(D32,'Cấu Hình Học Phí'!$A$8:$B$11,2,FALSE) | H32: =F32*G32 | I32: 1 | J32: =I32*'Cấu Hình Học Phí'!$B$5 | K32: 0 | L32: =H32+J32-K32 | M32: 2200000 | N32: 0 | O32: =MAX(0,M32-N32-L32) | P32: =MAX(0,L32-(M32-N32)) | Q32: 30/09/2025 | R32: PT2025-00029 | S32: Chưa nộp phí phụ đạo 1 môn
A33: 251210818 | B33: NGUYỄN ĐỨC CƯƠNG | C33: Công nghệ thông tin 1 K66 | D33: Năm 2 | E33: 2026_2027 | F33: 4 | G33: =VLOOKUP(D33,'Cấu Hình Học Phí'!$A$8:$B$11,2,FALSE) | H33: =F33*G33 | I33: 0 | J33: =I33*'Cấu Hình Học Phí'!$B$5 | K33: 0 | L33: =H33+J33-K33 | M33: 2420000 | N33: 0 | O33: =MAX(0,M33-N33-L33) | P33: =MAX(0,L33-(M33-N33)) | Q33: 30/09/2026 | R33: PT2026-00030
A34: 251210818 | B34: NGUYỄN ĐỨC CƯƠNG | C34: Công nghệ thông tin 1 K66 | D34: Năm 3 | E34: 2027_2028 | F34: 4 | G34: =VLOOKUP(D34,'Cấu Hình Học Phí'!$A$8:$B$11,2,FALSE) | H34: =F34*G34 | I34: 1 | J34: =I34*'Cấu Hình Học Phí'!$B$5 | K34: 0 | L34: =H34+J34-K34 | M34: 3662000 | N34: 0 | O34: =MAX(0,M34-N34-L34) | P34: =MAX(0,L34-(M34-N34)) | Q34: 30/09/2027 | R34: PT2027-00031
A35: 251210818 | B35: NGUYỄN ĐỨC CƯƠNG | C35: Công nghệ thông tin 1 K66 | D35: Năm 4 | E35: 2028_2029 | F35: 1 | G35: =VLOOKUP(D35,'Cấu Hình Học Phí'!$A$8:$B$11,2,FALSE) | H35: =F35*G35 | I35: 0 | J35: =I35*'Cấu Hình Học Phí'!$B$5 | K35: 0 | L35: =H35+J35-K35 | M35: 732050 | N35: 0 | O35: =MAX(0,M35-N35-L35) | P35: =MAX(0,L35-(M35-N35)) | Q35: 30/09/2028 | R35: PT2028-00032
A36: 251230821 | B36: VŨ MẠNH CƯỜNG | C36: Công nghệ thông tin 1 K66 | D36: Năm 1 | E36: 2025_2026 | F36: 4 | G36: =VLOOKUP(D36,'Cấu Hình Học Phí'!$A$8:$B$11,2,FALSE) | H36: =F36*G36 | I36: 0 | J36: =I36*'Cấu Hình Học Phí'!$B$5 | K36: 0 | L36: =H36+J36-K36 | M36: 2200000 | N36: 0 | O36: =MAX(0,M36-N36-L36) | P36: =MAX(0,L36-(M36-N36)) | Q36: 30/09/2025 | R36: PT2025-00033
A37: 251230821 | B37: VŨ MẠNH CƯỜNG | C37: Công nghệ thông tin 1 K66 | D37: Năm 2 | E37: 2026_2027 | F37: 4 | G37: =VLOOKUP(D37,'Cấu Hình Học Phí'!$A$8:$B$11,2,FALSE) | H37: =F37*G37 | I37: 0 | J37: =I37*'Cấu Hình Học Phí'!$B$5 | K37: 0 | L37: =H37+J37-K37 | M37: 2420000 | N37: 0 | O37: =MAX(0,M37-N37-L37) | P37: =MAX(0,L37-(M37-N37)) | Q37: 30/09/2026 | R37: PT2026-00034
A38: 251230821 | B38: VŨ MẠNH CƯỜNG | C38: Công nghệ thông tin 1 K66 | D38: Năm 3 | E38: 2027_2028 | F38: 4 | G38: =VLOOKUP(D38,'Cấu Hình Học Phí'!$A$8:$B$11,2,FALSE) | H38: =F38*G38 | I38: 1 | J38: =I38*'Cấu Hình Học Phí'!$B$5 | K38: 0 | L38: =H38+J38-K38 | M38: 3662000 | N38: 0 | O38: =MAX(0,M38-N38-L38) | P38: =MAX(0,L38-(M38-N38)) | Q38: 30/09/2027 | R38: PT2027-00035
A39: 251230821 | B39: VŨ MẠNH CƯỜNG | C39: Công nghệ thông tin 1 K66 | D39: Năm 4 | E39: 2028_2029 | F39: 1 | G39: =VLOOKUP(D39,'Cấu Hình Học Phí'!$A$8:$B$11,2,FALSE) | H39: =F39*G39 | I39: 0 | J39: =I39*'Cấu Hình Học Phí'!$B$5 | K39: 0 | L39: =H39+J39-K39 | M39: 732050 | N39: 0 | O39: =MAX(0,M39-N39-L39) | P39: =MAX(0,L39-(M39-N39)) | Q39: 30/09/2028 | R39: PT2028-00036
A40: 251230822 | B40: NGUYỄN KHÁNH DOANH | C40: Công nghệ thông tin 1 K66 | D40: Năm 1 | E40: 2025_2026 | F40: 4 | G40: =VLOOKUP(D40,'Cấu Hình Học Phí'!$A$8:$B$11,2,FALSE) | H40: =F40*G40 | I40: 1 | J40: =I40*'Cấu Hình Học Phí'!$B$5 | K40: 0 | L40: =H40+J40-K40 | M40: 2200000 | N40: 0 | O40: =MAX(0,M40-N40-L40) | P40: =MAX(0,L40-(M40-N40)) | Q40: 30/09/2025 | R40: PT2025-00037 | S40: Chưa nộp phí phụ đạo 1 môn
A41: 251230822 | B41: NGUYỄN KHÁNH DOANH | C41: Công nghệ thông tin 1 K66 | D41: Năm 2 | E41: 2026_2027 | F41: 4 | G41: =VLOOKUP(D41,'Cấu Hình Học Phí'!$A$8:$B$11,2,FALSE) | H41: =F41*G41 | I41: 1 | J41: =I41*'Cấu Hình Học Phí'!$B$5 | K41: 0 | L41: =H41+J41-K41 | M41: 3420000 | N41: 0 | O41: =MAX(0,M41-N41-L41) | P41: =MAX(0,L41-(M41-N41)) | Q41: 30/09/2026 | R41: PT2026-00038
...

Sheet Tổng Hợp Học Phí
A1: TỔNG HỢP HỌC PHÍ THEO SINH VIÊN
A3: MSV | B3: Họ và tên | C3: Lớp | D3: Học phí môn học | E3: Phí phụ đạo | F3: Miễn giảm | G3: Học phí phải nộp | H3: Học phí đã nộp | I3: Học phí thừa | J3: Học phí còn nợ | K3: Trạng thái
A4: 251230808 | B4: CHU ĐỨC ÁNH | C4: Công nghệ thông tin 1 K66 | D4: =SUMIFS('Chi Tiết Học Phí'!$H$4:$H$1023,'Chi Tiết Học Phí'!$A$4:$A$1023,A4) | E4: =SUMIFS('Chi Tiết Học Phí'!$J$4:$J$1023,'Chi Tiết Học Phí'!$A$4:$A$1023,A4) | F4: =SUMIFS('Chi Tiết Học Phí'!$K$4:$K$1023,'Chi Tiết Học Phí'!$A$4:$A$1023,A4) | G4: =SUMIFS('Chi Tiết Học Phí'!$L$4:$L$1023,'Chi Tiết Học Phí'!$A$4:$A$1023,A4) | H4: =SUMIFS('Chi Tiết Học Phí'!$M$4:$M$1023,'Chi Tiết Học Phí'!$A$4:$A$1023,A4)-SUMIFS('Chi Tiết Học Phí'!$N$4:$N$1023,'Chi Tiết Học Phí'!$A$4:$A$1023,A4) | I4: =SUMIFS('Chi Tiết Học Phí'!$O$4:$O$1023,'Chi Tiết Học Phí'!$A$4:$A$1023,A4) | J4: =SUMIFS('Chi Tiết Học Phí'!$P$4:$P$1023,'Chi Tiết Học Phí'!$A$4:$A$1023,A4) | K4: =IF(J4>0,"Còn nợ","Đã hoàn thành")
A5: 251210800 | B5: LÊ QUANG ANH | C5: Công nghệ thông tin 1 K66 | D5: =SUMIFS('Chi Tiết Học Phí'!$H$4:$H$1023,'Chi Tiết Học Phí'!$A$4:$A$1023,A5) | E5: =SUMIFS('Chi Tiết Học Phí'!$J$4:$J$1023,'Chi Tiết Học Phí'!$A$4:$A$1023,A5) | F5: =SUMIFS('Chi Tiết Học Phí'!$K$4:$K$1023,'Chi Tiết Học Phí'!$A$4:$A$1023,A5) | G5: =SUMIFS('Chi Tiết Học Phí'!$L$4:$L$1023,'Chi Tiết Học Phí'!$A$4:$A$1023,A5) | H5: =SUMIFS('Chi Tiết Học Phí'!$M$4:$M$1023,'Chi Tiết Học Phí'!$A$4:$A$1023,A5)-SUMIFS('Chi Tiết Học Phí'!$N$4:$N$1023,'Chi Tiết Học Phí'!$A$4:$A$1023,A5) | I5: =SUMIFS('Chi Tiết Học Phí'!$O$4:$O$1023,'Chi Tiết Học Phí'!$A$4:$A$1023,A5) | J5: =SUMIFS('Chi Tiết Học Phí'!$P$4:$P$1023,'Chi Tiết Học Phí'!$A$4:$A$1023,A5) | K5: =IF(J5>0,"Còn nợ","Đã hoàn thành")
A6: 251230801 | B6: NGÔ AN ĐỨC ANH | C6: Công nghệ thông tin 1 K66 | D6: =SUMIFS('Chi Tiết Học Phí'!$H$4:$H$1023,'Chi Tiết Học Phí'!$A$4:$A$1023,A6) | E6: =SUMIFS('Chi Tiết Học Phí'!$J$4:$J$1023,'Chi Tiết Học Phí'!$A$4:$A$1023,A6) | F6: =SUMIFS('Chi Tiết Học Phí'!$K$4:$K$1023,'Chi Tiết Học Phí'!$A$4:$A$1023,A6) | G6: =SUMIFS('Chi Tiết Học Phí'!$L$4:$L$1023,'Chi Tiết Học Phí'!$A$4:$A$1023,A6) | H6: =SUMIFS('Chi Tiết Học Phí'!$M$4:$M$1023,'Chi Tiết Học Phí'!$A$4:$A$1023,A6)-SUMIFS('Chi Tiết Học Phí'!$N$4:$N$1023,'Chi Tiết Học Phí'!$A$4:$A$1023,A6) | I6: =SUMIFS('Chi Tiết Học Phí'!$O$4:$O$1023,'Chi Tiết Học Phí'!$A$4:$A$1023,A6) | J6: =SUMIFS('Chi Tiết Học Phí'!$P$4:$P$1023,'Chi Tiết Học Phí'!$A$4:$A$1023,A6) | K6: =IF(J6>0,"Còn nợ","Đã hoàn thành")
A7: 251230807 | B7: TÔ VIỆT ANH | C7: Công nghệ thông tin 1 K66 | D7: =SUMIFS('Chi Tiết Học Phí'!$H$4:$H$1023,'Chi Tiết Học Phí'!$A$4:$A$1023,A7) | E7: =SUMIFS('Chi Tiết Học Phí'!$J$4:$J$1023,'Chi Tiết Học Phí'!$A$4:$A$1023,A7) | F7: =SUMIFS('Chi Tiết Học Phí'!$K$4:$K$1023,'Chi Tiết Học Phí'!$A$4:$A$1023,A7) | G7: =SUMIFS('Chi Tiết Học Phí'!$L$4:$L$1023,'Chi Tiết Học Phí'!$A$4:$A$1023,A7) | H7: =SUMIFS('Chi Tiết Học Phí'!$M$4:$M$1023,'Chi Tiết Học Phí'!$A$4:$A$1023,A7)-SUMIFS('Chi Tiết Học Phí'!$N$4:$N$1023,'Chi Tiết Học Phí'!$A$4:$A$1023,A7) | I7: =SUMIFS('Chi Tiết Học Phí'!$O$4:$O$1023,'Chi Tiết Học Phí'!$A$4:$A$1023,A7) | J7: =SUMIFS('Chi Tiết Học Phí'!$P$4:$P$1023,'Chi Tiết Học Phí'!$A$4:$A$1023,A7) | K7: =IF(J7>0,"Còn nợ","Đã hoàn thành")
A8: 251230813 | B8: TRẦN MẬU BẮC | C8: Công nghệ thông tin 1 K66 | D8: =SUMIFS('Chi Tiết Học Phí'!$H$4:$H$1023,'Chi Tiết Học Phí'!$A$4:$A$1023,A8) | E8: =SUMIFS('Chi Tiết Học Phí'!$J$4:$J$1023,'Chi Tiết Học Phí'!$A$4:$A$1023,A8) | F8: =SUMIFS('Chi Tiết Học Phí'!$K$4:$K$1023,'Chi Tiết Học Phí'!$A$4:$A$1023,A8) | G8: =SUMIFS('Chi Tiết Học Phí'!$L$4:$L$1023,'Chi Tiết Học Phí'!$A$4:$A$1023,A8) | H8: =SUMIFS('Chi Tiết Học Phí'!$M$4:$M$1023,'Chi Tiết Học Phí'!$A$4:$A$1023,A8)-SUMIFS('Chi Tiết Học Phí'!$N$4:$N$1023,'Chi Tiết Học Phí'!$A$4:$A$1023,A8) | I8: =SUMIFS('Chi Tiết Học Phí'!$O$4:$O$1023,'Chi Tiết Học Phí'!$A$4:$A$1023,A8) | J8: =SUMIFS('Chi Tiết Học Phí'!$P$4:$P$1023,'Chi Tiết Học Phí'!$A$4:$A$1023,A8) | K8: =IF(J8>0,"Còn nợ","Đã hoàn thành")
A9: 251230811 | B9: NGUYỄN VĂN CHÍ BẢO | C9: Công nghệ thông tin 1 K66 | D9: =SUMIFS('Chi Tiết Học Phí'!$H$4:$H$1023,'Chi Tiết Học Phí'!$A$4:$A$1023,A9) | E9: =SUMIFS('Chi Tiết Học Phí'!$J$4:$J$1023,'Chi Tiết Học Phí'!$A$4:$A$1023,A9) | F9: =SUMIFS('Chi Tiết Học Phí'!$K$4:$K$1023,'Chi Tiết Học Phí'!$A$4:$A$1023,A9) | G9: =SUMIFS('Chi Tiết Học Phí'!$L$4:$L$1023,'Chi Tiết Học Phí'!$A$4:$A$1023,A9) | H9: =SUMIFS('Chi Tiết Học Phí'!$M$4:$M$1023,'Chi Tiết Học Phí'!$A$4:$A$1023,A9)-SUMIFS('Chi Tiết Học Phí'!$N$4:$N$1023,'Chi Tiết Học Phí'!$A$4:$A$1023,A9) | I9: =SUMIFS('Chi Tiết Học Phí'!$O$4:$O$1023,'Chi Tiết Học Phí'!$A$4:$A$1023,A9) | J9: =SUMIFS('Chi Tiết Học Phí'!$P$4:$P$1023,'Chi Tiết Học Phí'!$A$4:$A$1023,A9) | K9: =IF(J9>0,"Còn nợ","Đã hoàn thành")
A10: 251230812 | B10: NGUYỄN VĂN GIA BẢO | C10: Công nghệ thông tin 1 K66 | D10: =SUMIFS('Chi Tiết Học Phí'!$H$4:$H$1023,'Chi Tiết Học Phí'!$A$4:$A$1023,A10) | E10: =SUMIFS('Chi Tiết Học Phí'!$J$4:$J$1023,'Chi Tiết Học Phí'!$A$4:$A$1023,A10) | F10: =SUMIFS('Chi Tiết Học Phí'!$K$4:$K$1023,'Chi Tiết Học Phí'!$A$4:$A$1023,A10) | G10: =SUMIFS('Chi Tiết Học Phí'!$L$4:$L$1023,'Chi Tiết Học Phí'!$A$4:$A$1023,A10) | H10: =SUMIFS('Chi Tiết Học Phí'!$M$4:$M$1023,'Chi Tiết Học Phí'!$A$4:$A$1023,A10)-SUMIFS('Chi Tiết Học Phí'!$N$4:$N$1023,'Chi Tiết Học Phí'!$A$4:$A$1023,A10) | I10: =SUMIFS('Chi Tiết Học Phí'!$O$4:$O$1023,'Chi Tiết Học Phí'!$A$4:$A$1023,A10) | J10: =SUMIFS('Chi Tiết Học Phí'!$P$4:$P$1023,'Chi Tiết Học Phí'!$A$4:$A$1023,A10) | K10: =IF(J10>0,"Còn nợ","Đã hoàn thành")
A11: 251210818 | B11: NGUYỄN ĐỨC CƯƠNG | C11: Công nghệ thông tin 1 K66 | D11: =SUMIFS('Chi Tiết Học Phí'!$H$4:$H$1023,'Chi Tiết Học Phí'!$A$4:$A$1023,A11) | E11: =SUMIFS('Chi Tiết Học Phí'!$J$4:$J$1023,'Chi Tiết Học Phí'!$A$4:$A$1023,A11) | F11: =SUMIFS('Chi Tiết Học Phí'!$K$4:$K$1023,'Chi Tiết Học Phí'!$A$4:$A$1023,A11) | G11: =SUMIFS('Chi Tiết Học Phí'!$L$4:$L$1023,'Chi Tiết Học Phí'!$A$4:$A$1023,A11) | H11: =SUMIFS('Chi Tiết Học Phí'!$M$4:$M$1023,'Chi Tiết Học Phí'!$A$4:$A$1023,A11)-SUMIFS('Chi Tiết Học Phí'!$N$4:$N$1023,'Chi Tiết Học Phí'!$A$4:$A$1023,A11) | I11: =SUMIFS('Chi Tiết Học Phí'!$O$4:$O$1023,'Chi Tiết Học Phí'!$A$4:$A$1023,A11) | J11: =SUMIFS('Chi Tiết Học Phí'!$P$4:$P$1023,'Chi Tiết Học Phí'!$A$4:$A$1023,A11) | K11: =IF(J11>0,"Còn nợ","Đã hoàn thành")
A12: 251230821 | B12: VŨ MẠNH CƯỜNG | C12: Công nghệ thông tin 1 K66 | D12: =SUMIFS('Chi Tiết Học Phí'!$H$4:$H$1023,'Chi Tiết Học Phí'!$A$4:$A$1023,A12) | E12: =SUMIFS('Chi Tiết Học Phí'!$J$4:$J$1023,'Chi Tiết Học Phí'!$A$4:$A$1023,A12) | F12: =SUMIFS('Chi Tiết Học Phí'!$K$4:$K$1023,'Chi Tiết Học Phí'!$A$4:$A$1023,A12) | G12: =SUMIFS('Chi Tiết Học Phí'!$L$4:$L$1023,'Chi Tiết Học Phí'!$A$4:$A$1023,A12) | H12: =SUMIFS('Chi Tiết Học Phí'!$M$4:$M$1023,'Chi Tiết Học Phí'!$A$4:$A$1023,A12)-SUMIFS('Chi Tiết Học Phí'!$N$4:$N$1023,'Chi Tiết Học Phí'!$A$4:$A$1023,A12) | I12: =SUMIFS('Chi Tiết Học Phí'!$O$4:$O$1023,'Chi Tiết Học Phí'!$A$4:$A$1023,A12) | J12: =SUMIFS('Chi Tiết Học Phí'!$P$4:$P$1023,'Chi Tiết Học Phí'!$A$4:$A$1023,A12) | K12: =IF(J12>0,"Còn nợ","Đã hoàn thành")
A13: 251230822 | B13: NGUYỄN KHÁNH DOANH | C13: Công nghệ thông tin 1 K66 | D13: =SUMIFS('Chi Tiết Học Phí'!$H$4:$H$1023,'Chi Tiết Học Phí'!$A$4:$A$1023,A13) | E13: =SUMIFS('Chi Tiết Học Phí'!$J$4:$J$1023,'Chi Tiết Học Phí'!$A$4:$A$1023,A13) | F13: =SUMIFS('Chi Tiết Học Phí'!$K$4:$K$1023,'Chi Tiết Học Phí'!$A$4:$A$1023,A13) | G13: =SUMIFS('Chi Tiết Học Phí'!$L$4:$L$1023,'Chi Tiết Học Phí'!$A$4:$A$1023,A13) | H13: =SUMIFS('Chi Tiết Học Phí'!$M$4:$M$1023,'Chi Tiết Học Phí'!$A$4:$A$1023,A13)-SUMIFS('Chi Tiết Học Phí'!$N$4:$N$1023,'Chi Tiết Học Phí'!$A$4:$A$1023,A13) | I13: =SUMIFS('Chi Tiết Học Phí'!$O$4:$O$1023,'Chi Tiết Học Phí'!$A$4:$A$1023,A13) | J13: =SUMIFS('Chi Tiết Học Phí'!$P$4:$P$1023,'Chi Tiết Học Phí'!$A$4:$A$1023,A13) | K13: =IF(J13>0,"Còn nợ","Đã hoàn thành")
A14: 251210825 | B14: ĐỖ QUANG DŨNG | C14: Công nghệ thông tin 1 K66 | D14: =SUMIFS('Chi Tiết Học Phí'!$H$4:$H$1023,'Chi Tiết Học Phí'!$A$4:$A$1023,A14) | E14: =SUMIFS('Chi Tiết Học Phí'!$J$4:$J$1023,'Chi Tiết Học Phí'!$A$4:$A$1023,A14) | F14: =SUMIFS('Chi Tiết Học Phí'!$K$4:$K$1023,'Chi Tiết Học Phí'!$A$4:$A$1023,A14) | G14: =SUMIFS('Chi Tiết Học Phí'!$L$4:$L$1023,'Chi Tiết Học Phí'!$A$4:$A$1023,A14) | H14: =SUMIFS('Chi Tiết Học Phí'!$M$4:$M$1023,'Chi Tiết Học Phí'!$A$4:$A$1023,A14)-SUMIFS('Chi Tiết Học Phí'!$N$4:$N$1023,'Chi Tiết Học Phí'!$A$4:$A$1023,A14) | I14: =SUMIFS('Chi Tiết Học Phí'!$O$4:$O$1023,'Chi Tiết Học Phí'!$A$4:$A$1023,A14) | J14: =SUMIFS('Chi Tiết Học Phí'!$P$4:$P$1023,'Chi Tiết Học Phí'!$A$4:$A$1023,A14) | K14: =IF(J14>0,"Còn nợ","Đã hoàn thành")
A15: 251210833 | B15: NGUYỄN TÙNG DƯƠNG | C15: Công nghệ thông tin 1 K66 | D15: =SUMIFS('Chi Tiết Học Phí'!$H$4:$H$1023,'Chi Tiết Học Phí'!$A$4:$A$1023,A15) | E15: =SUMIFS('Chi Tiết Học Phí'!$J$4:$J$1023,'Chi Tiết Học Phí'!$A$4:$A$1023,A15) | F15: =SUMIFS('Chi Tiết Học Phí'!$K$4:$K$1023,'Chi Tiết Học Phí'!$A$4:$A$1023,A15) | G15: =SUMIFS('Chi Tiết Học Phí'!$L$4:$L$1023,'Chi Tiết Học Phí'!$A$4:$A$1023,A15) | H15: =SUMIFS('Chi Tiết Học Phí'!$M$4:$M$1023,'Chi Tiết Học Phí'!$A$4:$A$1023,A15)-SUMIFS('Chi Tiết Học Phí'!$N$4:$N$1023,'Chi Tiết Học Phí'!$A$4:$A$1023,A15) | I15: =SUMIFS('Chi Tiết Học Phí'!$O$4:$O$1023,'Chi Tiết Học Phí'!$A$4:$A$1023,A15) | J15: =SUMIFS('Chi Tiết Học Phí'!$P$4:$P$1023,'Chi Tiết Học Phí'!$A$4:$A$1023,A15) | K15: =IF(J15>0,"Còn nợ","Đã hoàn thành")
... A258: 253610701 | B258: NGUYỄN ĐĂNG VIỆT | C258: Khoa học máy tính K66 | D258: =SUMIFS('Chi Tiết Học Phí'!$H$4:$H$1023,'Chi Tiết Học Phí'!$A$4:$A$1023,A258) | E258: =SUMIFS('Chi Tiết Học Phí'!$J$4:$J$1023,'Chi Tiết Học Phí'!$A$4:$A$1023,A258) | F258: =SUMIFS('Chi Tiết Học Phí'!$K$4:$K$1023,'Chi Tiết Học Phí'!$A$4:$A$1023,A258) | G258: =SUMIFS('Chi Tiết Học Phí'!$L$4:$L$1023,'Chi Tiết Học Phí'!$A$4:$A$1023,A258) | H258: =SUMIFS('Chi Tiết Học Phí'!$M$4:$M$1023,'Chi Tiết Học Phí'!$A$4:$A$1023,A258)-SUMIFS('Chi Tiết Học Phí'!$N$4:$N$1023,'Chi Tiết Học Phí'!$A$4:$A$1023,A258) | I258: =SUMIFS('Chi Tiết Học Phí'!$O$4:$O$1023,'Chi Tiết Học Phí'!$A$4:$A$1023,A258) | J258: =SUMIFS('Chi Tiết Học Phí'!$P$4:$P$1023,'Chi Tiết Học Phí'!$A$4:$A$1023,A258) | K258: =IF(J258>0,"Còn nợ","Đã hoàn thành")
